2025-04-28 20:30:40,716 INFO    StreamThr :240316 [internal.py:wandb_internal():85] W&B internal server running at pid: 240316, started at: 2025-04-28 20:30:40.716466
2025-04-28 20:30:40,717 DEBUG   HandlerThread:240316 [handler.py:handle_request():158] handle_request: status
2025-04-28 20:30:40,720 INFO    WriterThread:240316 [datastore.py:open_for_write():87] open: /home/levi/Desktop/MOORE-TDMPC/moore_tdmpc/logs/mw-reach/42/moore-tdmpc2-mt30/wandb/run-20250428_203040-6crtmllm/run-6crtmllm.wandb
2025-04-28 20:30:40,720 DEBUG   SenderThread:240316 [sender.py:send():379] send: header
2025-04-28 20:30:40,738 DEBUG   SenderThread:240316 [sender.py:send():379] send: run
2025-04-28 20:30:45,739 DEBUG   HandlerThread:240316 [handler.py:handle_request():158] handle_request: keepalive
2025-04-28 20:30:50,740 DEBUG   HandlerThread:240316 [handler.py:handle_request():158] handle_request: keepalive
2025-04-28 20:30:55,741 DEBUG   HandlerThread:240316 [handler.py:handle_request():158] handle_request: keepalive
2025-04-28 20:31:00,742 DEBUG   HandlerThread:240316 [handler.py:handle_request():158] handle_request: keepalive
2025-04-28 20:31:05,742 DEBUG   HandlerThread:240316 [handler.py:handle_request():158] handle_request: keepalive
2025-04-28 20:31:06,740 INFO    SenderThread:240316 [retry.py:__call__():172] Retry attempt failed:
Traceback (most recent call last):
  File "/home/levi/anaconda3/envs/tdmpc2/lib/python3.9/site-packages/urllib3/connectionpool.py", line 773, in urlopen
    self._prepare_proxy(conn)
  File "/home/levi/anaconda3/envs/tdmpc2/lib/python3.9/site-packages/urllib3/connectionpool.py", line 1042, in _prepare_proxy
    conn.connect()
  File "/home/levi/anaconda3/envs/tdmpc2/lib/python3.9/site-packages/urllib3/connection.py", line 741, in connect
    sock_and_verified = _ssl_wrap_socket_and_match_hostname(
  File "/home/levi/anaconda3/envs/tdmpc2/lib/python3.9/site-packages/urllib3/connection.py", line 920, in _ssl_wrap_socket_and_match_hostname
    ssl_sock = ssl_wrap_socket(
  File "/home/levi/anaconda3/envs/tdmpc2/lib/python3.9/site-packages/urllib3/util/ssl_.py", line 460, in ssl_wrap_socket
    ssl_sock = _ssl_wrap_socket_impl(sock, context, tls_in_tls, server_hostname)
  File "/home/levi/anaconda3/envs/tdmpc2/lib/python3.9/site-packages/urllib3/util/ssl_.py", line 504, in _ssl_wrap_socket_impl
    return ssl_context.wrap_socket(sock, server_hostname=server_hostname)
  File "/home/levi/anaconda3/envs/tdmpc2/lib/python3.9/ssl.py", line 501, in wrap_socket
    return self.sslsocket_class._create(
  File "/home/levi/anaconda3/envs/tdmpc2/lib/python3.9/ssl.py", line 1074, in _create
    self.do_handshake()
  File "/home/levi/anaconda3/envs/tdmpc2/lib/python3.9/ssl.py", line 1343, in do_handshake
    self._sslobj.do_handshake()
ConnectionResetError: [Errno 104] Connection reset by peer

During handling of the above exception, another exception occurred:

Traceback (most recent call last):
  File "/home/levi/anaconda3/envs/tdmpc2/lib/python3.9/site-packages/requests/adapters.py", line 667, in send
    resp = conn.urlopen(
  File "/home/levi/anaconda3/envs/tdmpc2/lib/python3.9/site-packages/urllib3/connectionpool.py", line 841, in urlopen
    retries = retries.increment(
  File "/home/levi/anaconda3/envs/tdmpc2/lib/python3.9/site-packages/urllib3/util/retry.py", line 474, in increment
    raise reraise(type(error), error, _stacktrace)
  File "/home/levi/anaconda3/envs/tdmpc2/lib/python3.9/site-packages/urllib3/util/util.py", line 38, in reraise
    raise value.with_traceback(tb)
  File "/home/levi/anaconda3/envs/tdmpc2/lib/python3.9/site-packages/urllib3/connectionpool.py", line 773, in urlopen
    self._prepare_proxy(conn)
  File "/home/levi/anaconda3/envs/tdmpc2/lib/python3.9/site-packages/urllib3/connectionpool.py", line 1042, in _prepare_proxy
    conn.connect()
  File "/home/levi/anaconda3/envs/tdmpc2/lib/python3.9/site-packages/urllib3/connection.py", line 741, in connect
    sock_and_verified = _ssl_wrap_socket_and_match_hostname(
  File "/home/levi/anaconda3/envs/tdmpc2/lib/python3.9/site-packages/urllib3/connection.py", line 920, in _ssl_wrap_socket_and_match_hostname
    ssl_sock = ssl_wrap_socket(
  File "/home/levi/anaconda3/envs/tdmpc2/lib/python3.9/site-packages/urllib3/util/ssl_.py", line 460, in ssl_wrap_socket
    ssl_sock = _ssl_wrap_socket_impl(sock, context, tls_in_tls, server_hostname)
  File "/home/levi/anaconda3/envs/tdmpc2/lib/python3.9/site-packages/urllib3/util/ssl_.py", line 504, in _ssl_wrap_socket_impl
    return ssl_context.wrap_socket(sock, server_hostname=server_hostname)
  File "/home/levi/anaconda3/envs/tdmpc2/lib/python3.9/ssl.py", line 501, in wrap_socket
    return self.sslsocket_class._create(
  File "/home/levi/anaconda3/envs/tdmpc2/lib/python3.9/ssl.py", line 1074, in _create
    self.do_handshake()
  File "/home/levi/anaconda3/envs/tdmpc2/lib/python3.9/ssl.py", line 1343, in do_handshake
    self._sslobj.do_handshake()
urllib3.exceptions.ProtocolError: ('Connection aborted.', ConnectionResetError(104, 'Connection reset by peer'))

During handling of the above exception, another exception occurred:

Traceback (most recent call last):
  File "/home/levi/anaconda3/envs/tdmpc2/lib/python3.9/site-packages/wandb/sdk/lib/retry.py", line 131, in __call__
    result = self._call_fn(*args, **kwargs)
  File "/home/levi/anaconda3/envs/tdmpc2/lib/python3.9/site-packages/wandb/sdk/internal/internal_api.py", line 345, in execute
    return self.client.execute(*args, **kwargs)  # type: ignore
  File "/home/levi/anaconda3/envs/tdmpc2/lib/python3.9/site-packages/wandb/vendor/gql-0.2.0/wandb_gql/client.py", line 52, in execute
    result = self._get_result(document, *args, **kwargs)
  File "/home/levi/anaconda3/envs/tdmpc2/lib/python3.9/site-packages/wandb/vendor/gql-0.2.0/wandb_gql/client.py", line 60, in _get_result
    return self.transport.execute(document, *args, **kwargs)
  File "/home/levi/anaconda3/envs/tdmpc2/lib/python3.9/site-packages/wandb/sdk/lib/gql_request.py", line 58, in execute
    request = self.session.post(self.url, **post_args)
  File "/home/levi/anaconda3/envs/tdmpc2/lib/python3.9/site-packages/requests/sessions.py", line 637, in post
    return self.request("POST", url, data=data, json=json, **kwargs)
  File "/home/levi/anaconda3/envs/tdmpc2/lib/python3.9/site-packages/requests/sessions.py", line 589, in request
    resp = self.send(prep, **send_kwargs)
  File "/home/levi/anaconda3/envs/tdmpc2/lib/python3.9/site-packages/requests/sessions.py", line 703, in send
    r = adapter.send(request, **kwargs)
  File "/home/levi/anaconda3/envs/tdmpc2/lib/python3.9/site-packages/requests/adapters.py", line 682, in send
    raise ConnectionError(err, request=request)
requests.exceptions.ConnectionError: ('Connection aborted.', ConnectionResetError(104, 'Connection reset by peer'))
2025-04-28 20:31:10,743 DEBUG   HandlerThread:240316 [handler.py:handle_request():158] handle_request: keepalive
2025-04-28 20:31:15,744 DEBUG   HandlerThread:240316 [handler.py:handle_request():158] handle_request: keepalive
2025-04-28 20:31:20,745 DEBUG   HandlerThread:240316 [handler.py:handle_request():158] handle_request: keepalive
2025-04-28 20:31:25,746 DEBUG   HandlerThread:240316 [handler.py:handle_request():158] handle_request: keepalive
2025-04-28 20:31:30,747 DEBUG   HandlerThread:240316 [handler.py:handle_request():158] handle_request: keepalive
2025-04-28 20:31:35,748 DEBUG   HandlerThread:240316 [handler.py:handle_request():158] handle_request: keepalive
2025-04-28 20:31:40,749 DEBUG   HandlerThread:240316 [handler.py:handle_request():158] handle_request: keepalive
2025-04-28 20:31:45,749 DEBUG   HandlerThread:240316 [handler.py:handle_request():158] handle_request: keepalive
2025-04-28 20:31:50,750 DEBUG   HandlerThread:240316 [handler.py:handle_request():158] handle_request: keepalive
2025-04-28 20:31:55,751 DEBUG   HandlerThread:240316 [handler.py:handle_request():158] handle_request: keepalive
2025-04-28 20:32:00,752 DEBUG   HandlerThread:240316 [handler.py:handle_request():158] handle_request: keepalive
2025-04-28 20:32:05,753 DEBUG   HandlerThread:240316 [handler.py:handle_request():158] handle_request: keepalive
2025-04-28 20:32:10,754 DEBUG   HandlerThread:240316 [handler.py:handle_request():158] handle_request: cancel
2025-04-28 20:32:10,754 DEBUG   HandlerThread:240316 [handler.py:handle_request():158] handle_request: cancel
2025-04-28 20:32:10,754 DEBUG   SenderThread:240316 [sender.py:send():388] Record cancelled: run
2025-04-28 20:32:10,754 DEBUG   HandlerThread:240316 [handler.py:handle_request():158] handle_request: status_report
2025-04-28 20:32:12,829 DEBUG   HandlerThread:240316 [handler.py:handle_request():158] handle_request: shutdown
2025-04-28 20:32:12,829 INFO    HandlerThread:240316 [handler.py:finish():882] shutting down handler
2025-04-28 20:32:13,754 INFO    SenderThread:240316 [sender.py:finish():1608] shutting down sender
2025-04-28 20:32:13,755 INFO    WriterThread:240316 [datastore.py:close():296] close: /home/levi/Desktop/MOORE-TDMPC/moore_tdmpc/logs/mw-reach/42/moore-tdmpc2-mt30/wandb/run-20250428_203040-6crtmllm/run-6crtmllm.wandb
