2025-04-24 13:37:37,406 INFO    MainThread:2250220 [wandb_setup.py:_flush():76] Current SDK version is 0.17.4
2025-04-24 13:37:37,407 INFO    MainThread:2250220 [wandb_setup.py:_flush():76] Configure stats pid to 2250220
2025-04-24 13:37:37,407 INFO    MainThread:2250220 [wandb_setup.py:_flush():76] Loading settings from /home/levi/.config/wandb/settings
2025-04-24 13:37:37,407 INFO    MainThread:2250220 [wandb_setup.py:_flush():76] Loading settings from /home/levi/Desktop/MOORE-TDMPC/moore_tdmpc/outputs/2025-04-24/13-37-30/wandb/settings
2025-04-24 13:37:37,407 INFO    MainThread:2250220 [wandb_setup.py:_flush():76] Loading settings from environment variables: {'silent': 'false'}
2025-04-24 13:37:37,407 INFO    MainThread:2250220 [wandb_setup.py:_flush():76] Applying setup settings: {'_disable_service': False}
2025-04-24 13:37:37,407 WARNING MainThread:2250220 [wandb_setup.py:_flush():76] Could not save program above cwd: /home/levi/Desktop/MOORE-TDMPC/moore_tdmpc/train_with_cprofile.py
2025-04-24 13:37:37,407 INFO    MainThread:2250220 [wandb_setup.py:_flush():76] Inferring run settings from compute environment: {'program_relpath': None, 'program_abspath': '/home/levi/Desktop/MOORE-TDMPC/moore_tdmpc/train_with_cprofile.py', 'program': '/home/levi/Desktop/MOORE-TDMPC/moore_tdmpc/train_with_cprofile.py'}
2025-04-24 13:37:37,407 INFO    MainThread:2250220 [wandb_setup.py:_flush():76] Applying login settings: {}
2025-04-24 13:37:37,407 INFO    MainThread:2250220 [wandb_init.py:_log_setup():529] Logging user logs to /home/levi/Desktop/MOORE-TDMPC/moore_tdmpc/logs/mw-hammer/42/moore-tdmpc2-mt30/wandb/run-20250424_133737-cybzsnsh/logs/debug.log
2025-04-24 13:37:37,407 INFO    MainThread:2250220 [wandb_init.py:_log_setup():530] Logging internal logs to /home/levi/Desktop/MOORE-TDMPC/moore_tdmpc/logs/mw-hammer/42/moore-tdmpc2-mt30/wandb/run-20250424_133737-cybzsnsh/logs/debug-internal.log
2025-04-24 13:37:37,407 INFO    MainThread:2250220 [wandb_init.py:init():569] calling init triggers
2025-04-24 13:37:37,407 INFO    MainThread:2250220 [wandb_init.py:init():576] wandb.init called with sweep_config: {}
config: {'env_type': 'MooreMultiTask', 'n_contexts': 10, 'obs_dim': 39, 'action_dim': 4, 'hidden_dim': 256, 'n_experts': 4, 'moore_temperature': 1.0, 'use_softmax': True, 'use_checkpoint': False, 'use_mixed_precision': True, 'gamma': 0.99, 'stddev': 0.1, 'actor_updates': 2, 'use_ema': True, 'ensemble_size': 5, 'update_freq': 2, 'seed': 42, 'device': device(type='cuda', index=0), 'task': 'mw-hammer', 'obs': 'state', 'multitask': False, 'steps': 10000000, 'batch_size': 1024, 'reward_coef': 0.1, 'value_coef': 0.25, 'consistency_coef': 20, 'rho': 0.5, 'lr': 0.0003, 'enc_lr_scale': 0.3, 'grad_clip_norm': 20, 'tau': 0.01, 'discount_denom': 5, 'discount_min': 0.95, 'discount_max': 0.995, 'buffer_size': 100000, 'exp_name': 'moore-tdmpc2-mt30', 'eval_freq': 5000, 'eval_episodes': 10, 'moore': {'n_experts': 4, 'temperature': 1.0, 'use_softmax': True, 'debug_task_emb': False}, 'mpc': True, 'iterations': 4, 'num_samples': 512, 'num_elites': 64, 'num_pi_trajs': 24, 'horizon': 5, 'min_std': 0.05, 'max_std': 2, 'temperature': 0.5, 'log_std_min': -10, 'log_std_max': 2, 'entropy_coef': 0.0001, 'model_size': 5, 'num_enc_layers': 2, 'enc_dim': 256, 'num_channels': 32, 'mlp_dim': 512, 'latent_dim': 512, 'task_dim': 0, 'num_q': 5, 'dropout': 0.01, 'simnorm_dim': 8, 'num_bins': 101, 'vmin': -10, 'vmax': 10, 'wandb_project': 'moore-tdmpc2', 'wandb_entity': 'OA-MBRL', 'wandb_silent': False, 'enable_wandb': True, 'save_csv': True, 'save_video': False, 'save_agent': True, 'compile': True, 'compile_dynamics': True, 'compile_loss': True, 'work_dir': PosixPath('/home/levi/Desktop/MOORE-TDMPC/moore_tdmpc/logs/mw-hammer/42/moore-tdmpc2-mt30'), 'task_title': 'Mw Hammer', 'tasks': ['mw-hammer'], 'obs_shape': {'state': (39,)}, 'episode_length': 100, 'obs_shapes': '???', 'episode_lengths': '???', 'seed_steps': 1000, 'bin_size': 0.2, 'data_dir': '/media/levi/Singe4linux/Moore-TDMPC/TDMPC2/data/mt30'}
2025-04-24 13:37:37,407 INFO    MainThread:2250220 [wandb_init.py:init():619] starting backend
2025-04-24 13:37:37,407 INFO    MainThread:2250220 [wandb_init.py:init():623] setting up manager
2025-04-24 13:37:37,410 INFO    MainThread:2250220 [backend.py:_multiprocessing_setup():105] multiprocessing start_methods=fork,spawn,forkserver, using: spawn
2025-04-24 13:37:37,411 INFO    MainThread:2250220 [wandb_init.py:init():631] backend started and connected
2025-04-24 13:37:37,415 INFO    MainThread:2250220 [wandb_init.py:init():720] updated telemetry
2025-04-24 13:37:37,415 INFO    MainThread:2250220 [wandb_init.py:init():753] communicating run to backend with 90.0 second timeout
2025-04-24 13:37:50,588 INFO    Thread-2  :2250220 [retry.py:__call__():172] Retry attempt failed:
Traceback (most recent call last):
  File "/home/levi/anaconda3/envs/tdmpc2/lib/python3.9/site-packages/urllib3/connectionpool.py", line 773, in urlopen
    self._prepare_proxy(conn)
  File "/home/levi/anaconda3/envs/tdmpc2/lib/python3.9/site-packages/urllib3/connectionpool.py", line 1042, in _prepare_proxy
    conn.connect()
  File "/home/levi/anaconda3/envs/tdmpc2/lib/python3.9/site-packages/urllib3/connection.py", line 741, in connect
    sock_and_verified = _ssl_wrap_socket_and_match_hostname(
  File "/home/levi/anaconda3/envs/tdmpc2/lib/python3.9/site-packages/urllib3/connection.py", line 920, in _ssl_wrap_socket_and_match_hostname
    ssl_sock = ssl_wrap_socket(
  File "/home/levi/anaconda3/envs/tdmpc2/lib/python3.9/site-packages/urllib3/util/ssl_.py", line 460, in ssl_wrap_socket
    ssl_sock = _ssl_wrap_socket_impl(sock, context, tls_in_tls, server_hostname)
  File "/home/levi/anaconda3/envs/tdmpc2/lib/python3.9/site-packages/urllib3/util/ssl_.py", line 504, in _ssl_wrap_socket_impl
    return ssl_context.wrap_socket(sock, server_hostname=server_hostname)
  File "/home/levi/anaconda3/envs/tdmpc2/lib/python3.9/ssl.py", line 501, in wrap_socket
    return self.sslsocket_class._create(
  File "/home/levi/anaconda3/envs/tdmpc2/lib/python3.9/ssl.py", line 1074, in _create
    self.do_handshake()
  File "/home/levi/anaconda3/envs/tdmpc2/lib/python3.9/ssl.py", line 1343, in do_handshake
    self._sslobj.do_handshake()
ConnectionResetError: [Errno 104] Connection reset by peer

During handling of the above exception, another exception occurred:

Traceback (most recent call last):
  File "/home/levi/anaconda3/envs/tdmpc2/lib/python3.9/site-packages/requests/adapters.py", line 667, in send
    resp = conn.urlopen(
  File "/home/levi/anaconda3/envs/tdmpc2/lib/python3.9/site-packages/urllib3/connectionpool.py", line 841, in urlopen
    retries = retries.increment(
  File "/home/levi/anaconda3/envs/tdmpc2/lib/python3.9/site-packages/urllib3/util/retry.py", line 474, in increment
    raise reraise(type(error), error, _stacktrace)
  File "/home/levi/anaconda3/envs/tdmpc2/lib/python3.9/site-packages/urllib3/util/util.py", line 38, in reraise
    raise value.with_traceback(tb)
  File "/home/levi/anaconda3/envs/tdmpc2/lib/python3.9/site-packages/urllib3/connectionpool.py", line 773, in urlopen
    self._prepare_proxy(conn)
  File "/home/levi/anaconda3/envs/tdmpc2/lib/python3.9/site-packages/urllib3/connectionpool.py", line 1042, in _prepare_proxy
    conn.connect()
  File "/home/levi/anaconda3/envs/tdmpc2/lib/python3.9/site-packages/urllib3/connection.py", line 741, in connect
    sock_and_verified = _ssl_wrap_socket_and_match_hostname(
  File "/home/levi/anaconda3/envs/tdmpc2/lib/python3.9/site-packages/urllib3/connection.py", line 920, in _ssl_wrap_socket_and_match_hostname
    ssl_sock = ssl_wrap_socket(
  File "/home/levi/anaconda3/envs/tdmpc2/lib/python3.9/site-packages/urllib3/util/ssl_.py", line 460, in ssl_wrap_socket
    ssl_sock = _ssl_wrap_socket_impl(sock, context, tls_in_tls, server_hostname)
  File "/home/levi/anaconda3/envs/tdmpc2/lib/python3.9/site-packages/urllib3/util/ssl_.py", line 504, in _ssl_wrap_socket_impl
    return ssl_context.wrap_socket(sock, server_hostname=server_hostname)
  File "/home/levi/anaconda3/envs/tdmpc2/lib/python3.9/ssl.py", line 501, in wrap_socket
    return self.sslsocket_class._create(
  File "/home/levi/anaconda3/envs/tdmpc2/lib/python3.9/ssl.py", line 1074, in _create
    self.do_handshake()
  File "/home/levi/anaconda3/envs/tdmpc2/lib/python3.9/ssl.py", line 1343, in do_handshake
    self._sslobj.do_handshake()
urllib3.exceptions.ProtocolError: ('Connection aborted.', ConnectionResetError(104, 'Connection reset by peer'))

During handling of the above exception, another exception occurred:

Traceback (most recent call last):
  File "/home/levi/anaconda3/envs/tdmpc2/lib/python3.9/site-packages/wandb/sdk/lib/retry.py", line 131, in __call__
    result = self._call_fn(*args, **kwargs)
  File "/home/levi/anaconda3/envs/tdmpc2/lib/python3.9/site-packages/wandb/sdk/internal/internal_api.py", line 345, in execute
    return self.client.execute(*args, **kwargs)  # type: ignore
  File "/home/levi/anaconda3/envs/tdmpc2/lib/python3.9/site-packages/wandb/vendor/gql-0.2.0/wandb_gql/client.py", line 52, in execute
    result = self._get_result(document, *args, **kwargs)
  File "/home/levi/anaconda3/envs/tdmpc2/lib/python3.9/site-packages/wandb/vendor/gql-0.2.0/wandb_gql/client.py", line 60, in _get_result
    return self.transport.execute(document, *args, **kwargs)
  File "/home/levi/anaconda3/envs/tdmpc2/lib/python3.9/site-packages/wandb/sdk/lib/gql_request.py", line 58, in execute
    request = self.session.post(self.url, **post_args)
  File "/home/levi/anaconda3/envs/tdmpc2/lib/python3.9/site-packages/requests/sessions.py", line 637, in post
    return self.request("POST", url, data=data, json=json, **kwargs)
  File "/home/levi/anaconda3/envs/tdmpc2/lib/python3.9/site-packages/requests/sessions.py", line 589, in request
    resp = self.send(prep, **send_kwargs)
  File "/home/levi/anaconda3/envs/tdmpc2/lib/python3.9/site-packages/requests/sessions.py", line 703, in send
    r = adapter.send(request, **kwargs)
  File "/home/levi/anaconda3/envs/tdmpc2/lib/python3.9/site-packages/requests/adapters.py", line 682, in send
    raise ConnectionError(err, request=request)
requests.exceptions.ConnectionError: ('Connection aborted.', ConnectionResetError(104, 'Connection reset by peer'))
2025-04-24 13:38:36,569 INFO    MainThread:2250220 [wandb_run.py:_on_init():2402] communicating current version
2025-04-24 13:38:37,382 INFO    MainThread:2250220 [wandb_run.py:_on_init():2411] got version response upgrade_message: "wandb version 0.19.10 is available!  To upgrade, please run:\n $ pip install wandb --upgrade"

2025-04-24 13:38:37,382 INFO    MainThread:2250220 [wandb_init.py:init():804] starting run threads in backend
2025-04-24 13:38:38,348 INFO    MainThread:2250220 [wandb_run.py:_console_start():2380] atexit reg
2025-04-24 13:38:38,348 INFO    MainThread:2250220 [wandb_run.py:_redirect():2235] redirect: wrap_raw
2025-04-24 13:38:38,348 INFO    MainThread:2250220 [wandb_run.py:_redirect():2300] Wrapping output streams.
2025-04-24 13:38:38,348 INFO    MainThread:2250220 [wandb_run.py:_redirect():2325] Redirects installed.
2025-04-24 13:38:38,349 INFO    MainThread:2250220 [wandb_init.py:init():847] run started, returning control to user process
2025-04-24 13:39:14,122 WARNING MsgRouterThr:2250220 [router.py:message_loop():77] message_loop has been closed
